ERROR 2019-04-25 21:23:41,037 52817ms UsersController        MoveNext           - error in UsersController -> UpdateUserAsync: 
System.NullReferenceException: Referencia a objeto no establecida como instancia de un objeto.
   en DataAccessLayer.Repositories.UserRepository.<Update>d__6.MoveNext() en C:\Users\emoret\source\repos\WebAPIService\DataAccessLayer\Repositories\UserRepository.cs:línea 86
--- Fin del seguimiento de la pila de la ubicación anterior donde se produjo la excepción ---
   en System.Runtime.CompilerServices.TaskAwaiter.ThrowForNonSuccess(Task task)
   en System.Runtime.CompilerServices.TaskAwaiter.HandleNonSuccessAndDebuggerNotification(Task task)
   en System.Runtime.CompilerServices.TaskAwaiter`1.GetResult()
   en DataAccessLayer.UsersData.<Update>d__5.MoveNext() en C:\Users\emoret\source\repos\WebAPIService\DataAccessLayer\UsersData.cs:línea 36
--- Fin del seguimiento de la pila de la ubicación anterior donde se produjo la excepción ---
   en System.Runtime.CompilerServices.TaskAwaiter.ThrowForNonSuccess(Task task)
   en System.Runtime.CompilerServices.TaskAwaiter.HandleNonSuccessAndDebuggerNotification(Task task)
   en System.Runtime.CompilerServices.TaskAwaiter`1.GetResult()
   en BusinessLayer.UserBusiness.<Update>d__7.MoveNext()
--- Fin del seguimiento de la pila de la ubicación anterior donde se produjo la excepción ---
   en System.Runtime.CompilerServices.TaskAwaiter.ThrowForNonSuccess(Task task)
   en System.Runtime.CompilerServices.TaskAwaiter.HandleNonSuccessAndDebuggerNotification(Task task)
   en System.Runtime.CompilerServices.TaskAwaiter`1.GetResult()
   en WebAPIService.Controllers.UsersController.<UpdateUserAsync>d__7.MoveNext() en C:\Users\emoret\source\repos\WebAPIService\WebAPIService\Controllers\UsersController.cs:línea 88
ERROR 2019-04-25 21:23:59,363 71143ms UsersController        MoveNext           - error in UsersController -> UpdateUserAsync: 
System.NullReferenceException: Referencia a objeto no establecida como instancia de un objeto.
   en DataAccessLayer.Repositories.UserRepository.<Update>d__6.MoveNext() en C:\Users\emoret\source\repos\WebAPIService\DataAccessLayer\Repositories\UserRepository.cs:línea 86
--- Fin del seguimiento de la pila de la ubicación anterior donde se produjo la excepción ---
   en System.Runtime.CompilerServices.TaskAwaiter.ThrowForNonSuccess(Task task)
   en System.Runtime.CompilerServices.TaskAwaiter.HandleNonSuccessAndDebuggerNotification(Task task)
   en System.Runtime.CompilerServices.TaskAwaiter`1.GetResult()
   en DataAccessLayer.UsersData.<Update>d__5.MoveNext() en C:\Users\emoret\source\repos\WebAPIService\DataAccessLayer\UsersData.cs:línea 36
--- Fin del seguimiento de la pila de la ubicación anterior donde se produjo la excepción ---
   en System.Runtime.CompilerServices.TaskAwaiter.ThrowForNonSuccess(Task task)
   en System.Runtime.CompilerServices.TaskAwaiter.HandleNonSuccessAndDebuggerNotification(Task task)
   en System.Runtime.CompilerServices.TaskAwaiter`1.GetResult()
   en BusinessLayer.UserBusiness.<Update>d__7.MoveNext()
--- Fin del seguimiento de la pila de la ubicación anterior donde se produjo la excepción ---
   en System.Runtime.CompilerServices.TaskAwaiter.ThrowForNonSuccess(Task task)
   en System.Runtime.CompilerServices.TaskAwaiter.HandleNonSuccessAndDebuggerNotification(Task task)
   en System.Runtime.CompilerServices.TaskAwaiter`1.GetResult()
   en WebAPIService.Controllers.UsersController.<UpdateUserAsync>d__7.MoveNext() en C:\Users\emoret\source\repos\WebAPIService\WebAPIService\Controllers\UsersController.cs:línea 88
ERROR 2019-04-25 21:25:35,947 167727ms UsersController        MoveNext           - error in UsersController -> UpdateUserAsync: 
System.NullReferenceException: Referencia a objeto no establecida como instancia de un objeto.
   en DataAccessLayer.Repositories.UserRepository.<Update>d__6.MoveNext() en C:\Users\emoret\source\repos\WebAPIService\DataAccessLayer\Repositories\UserRepository.cs:línea 86
--- Fin del seguimiento de la pila de la ubicación anterior donde se produjo la excepción ---
   en System.Runtime.CompilerServices.TaskAwaiter.ThrowForNonSuccess(Task task)
   en System.Runtime.CompilerServices.TaskAwaiter.HandleNonSuccessAndDebuggerNotification(Task task)
   en System.Runtime.CompilerServices.TaskAwaiter`1.GetResult()
   en DataAccessLayer.UsersData.<Update>d__5.MoveNext() en C:\Users\emoret\source\repos\WebAPIService\DataAccessLayer\UsersData.cs:línea 36
--- Fin del seguimiento de la pila de la ubicación anterior donde se produjo la excepción ---
   en System.Runtime.CompilerServices.TaskAwaiter.ThrowForNonSuccess(Task task)
   en System.Runtime.CompilerServices.TaskAwaiter.HandleNonSuccessAndDebuggerNotification(Task task)
   en System.Runtime.CompilerServices.TaskAwaiter`1.GetResult()
   en BusinessLayer.UserBusiness.<Update>d__7.MoveNext()
--- Fin del seguimiento de la pila de la ubicación anterior donde se produjo la excepción ---
   en System.Runtime.CompilerServices.TaskAwaiter.ThrowForNonSuccess(Task task)
   en System.Runtime.CompilerServices.TaskAwaiter.HandleNonSuccessAndDebuggerNotification(Task task)
   en System.Runtime.CompilerServices.TaskAwaiter`1.GetResult()
   en WebAPIService.Controllers.UsersController.<UpdateUserAsync>d__7.MoveNext() en C:\Users\emoret\source\repos\WebAPIService\WebAPIService\Controllers\UsersController.cs:línea 88
ERROR 2019-04-25 21:44:51,083 382945ms UsersController        MoveNext           - error in UsersController -> UpdateUserAsync: 
System.Data.Entity.Infrastructure.DbUpdateException: Conflicting changes detected. This may happen when trying to insert multiple entities with the same key. ---> System.Data.Entity.Core.UpdateException: Conflicting changes detected. This may happen when trying to insert multiple entities with the same key.
   en System.Data.Entity.Core.Mapping.Update.Internal.TableChangeProcessor.DiagnoseKeyCollision(UpdateCompiler compiler, PropagatorResult change, CompositeKey key, PropagatorResult other)
   en System.Data.Entity.Core.Mapping.Update.Internal.TableChangeProcessor.ProcessKeys(UpdateCompiler compiler, List`1 changes, Set`1 keys)
   en System.Data.Entity.Core.Mapping.Update.Internal.TableChangeProcessor.CompileCommands(ChangeNode changeNode, UpdateCompiler compiler)
   en System.Data.Entity.Core.Mapping.Update.Internal.UpdateTranslator.<ProduceDynamicCommands>d__a.MoveNext()
   en System.Linq.Enumerable.<ConcatIterator>d__59`1.MoveNext()
   en System.Data.Entity.Core.Mapping.Update.Internal.UpdateCommandOrderer..ctor(IEnumerable`1 commands, UpdateTranslator translator)
   en System.Data.Entity.Core.Mapping.Update.Internal.UpdateTranslator.ProduceCommands()
   en System.Data.Entity.Core.Mapping.Update.Internal.UpdateTranslator.<UpdateAsync>d__0.MoveNext()
--- Fin del seguimiento de la pila de la ubicación anterior donde se produjo la excepción ---
   en System.Runtime.CompilerServices.TaskAwaiter.ThrowForNonSuccess(Task task)
   en System.Runtime.CompilerServices.TaskAwaiter.HandleNonSuccessAndDebuggerNotification(Task task)
   en System.Data.Entity.Core.Objects.ObjectContext.<ExecuteInTransactionAsync>d__3d`1.MoveNext()
--- Fin del seguimiento de la pila de la ubicación anterior donde se produjo la excepción ---
   en System.Runtime.CompilerServices.TaskAwaiter.ThrowForNonSuccess(Task task)
   en System.Runtime.CompilerServices.TaskAwaiter.HandleNonSuccessAndDebuggerNotification(Task task)
   en System.Data.Entity.Core.Objects.ObjectContext.<SaveChangesToStoreAsync>d__39.MoveNext()
--- Fin del seguimiento de la pila de la ubicación anterior donde se produjo la excepción ---
   en System.Runtime.CompilerServices.TaskAwaiter.ThrowForNonSuccess(Task task)
   en System.Runtime.CompilerServices.TaskAwaiter.HandleNonSuccessAndDebuggerNotification(Task task)
   en System.Data.Entity.SqlServer.DefaultSqlExecutionStrategy.<ExecuteAsyncImplementation>d__9`1.MoveNext()
--- Fin del seguimiento de la pila de la ubicación anterior donde se produjo la excepción ---
   en System.Runtime.CompilerServices.TaskAwaiter.ThrowForNonSuccess(Task task)
   en System.Runtime.CompilerServices.TaskAwaiter.HandleNonSuccessAndDebuggerNotification(Task task)
   en System.Data.Entity.Core.Objects.ObjectContext.<SaveChangesInternalAsync>d__31.MoveNext()
   --- Fin del seguimiento de la pila de la excepción interna ---
   en DataAccessLayer.Repositories.UserRepository.<Update>d__6.MoveNext() en C:\Users\emoret\source\repos\WebAPIService\DataAccessLayer\Repositories\UserRepository.cs:línea 86
--- Fin del seguimiento de la pila de la ubicación anterior donde se produjo la excepción ---
   en System.Runtime.CompilerServices.TaskAwaiter.ThrowForNonSuccess(Task task)
   en System.Runtime.CompilerServices.TaskAwaiter.HandleNonSuccessAndDebuggerNotification(Task task)
   en System.Runtime.CompilerServices.TaskAwaiter`1.GetResult()
   en DataAccessLayer.UsersData.<Update>d__5.MoveNext() en C:\Users\emoret\source\repos\WebAPIService\DataAccessLayer\UsersData.cs:línea 36
--- Fin del seguimiento de la pila de la ubicación anterior donde se produjo la excepción ---
   en System.Runtime.CompilerServices.TaskAwaiter.ThrowForNonSuccess(Task task)
   en System.Runtime.CompilerServices.TaskAwaiter.HandleNonSuccessAndDebuggerNotification(Task task)
   en System.Runtime.CompilerServices.TaskAwaiter`1.GetResult()
   en BusinessLayer.UserBusiness.<Update>d__7.MoveNext()
--- Fin del seguimiento de la pila de la ubicación anterior donde se produjo la excepción ---
   en System.Runtime.CompilerServices.TaskAwaiter.ThrowForNonSuccess(Task task)
   en System.Runtime.CompilerServices.TaskAwaiter.HandleNonSuccessAndDebuggerNotification(Task task)
   en System.Runtime.CompilerServices.TaskAwaiter`1.GetResult()
   en WebAPIService.Controllers.UsersController.<UpdateUserAsync>d__7.MoveNext() en C:\Users\emoret\source\repos\WebAPIService\WebAPIService\Controllers\UsersController.cs:línea 88
ERROR 2019-04-25 21:48:39,200 611062ms UsersController        MoveNext           - error in UsersController -> UpdateUserAsync: 
System.Data.Entity.Infrastructure.DbUpdateException: Conflicting changes detected. This may happen when trying to insert multiple entities with the same key. ---> System.Data.Entity.Core.UpdateException: Conflicting changes detected. This may happen when trying to insert multiple entities with the same key.
   en System.Data.Entity.Core.Mapping.Update.Internal.TableChangeProcessor.DiagnoseKeyCollision(UpdateCompiler compiler, PropagatorResult change, CompositeKey key, PropagatorResult other)
   en System.Data.Entity.Core.Mapping.Update.Internal.TableChangeProcessor.ProcessKeys(UpdateCompiler compiler, List`1 changes, Set`1 keys)
   en System.Data.Entity.Core.Mapping.Update.Internal.TableChangeProcessor.CompileCommands(ChangeNode changeNode, UpdateCompiler compiler)
   en System.Data.Entity.Core.Mapping.Update.Internal.UpdateTranslator.<ProduceDynamicCommands>d__a.MoveNext()
   en System.Linq.Enumerable.<ConcatIterator>d__59`1.MoveNext()
   en System.Data.Entity.Core.Mapping.Update.Internal.UpdateCommandOrderer..ctor(IEnumerable`1 commands, UpdateTranslator translator)
   en System.Data.Entity.Core.Mapping.Update.Internal.UpdateTranslator.ProduceCommands()
   en System.Data.Entity.Core.Mapping.Update.Internal.UpdateTranslator.<UpdateAsync>d__0.MoveNext()
--- Fin del seguimiento de la pila de la ubicación anterior donde se produjo la excepción ---
   en System.Runtime.CompilerServices.TaskAwaiter.ThrowForNonSuccess(Task task)
   en System.Runtime.CompilerServices.TaskAwaiter.HandleNonSuccessAndDebuggerNotification(Task task)
   en System.Data.Entity.Core.Objects.ObjectContext.<ExecuteInTransactionAsync>d__3d`1.MoveNext()
--- Fin del seguimiento de la pila de la ubicación anterior donde se produjo la excepción ---
   en System.Runtime.CompilerServices.TaskAwaiter.ThrowForNonSuccess(Task task)
   en System.Runtime.CompilerServices.TaskAwaiter.HandleNonSuccessAndDebuggerNotification(Task task)
   en System.Data.Entity.Core.Objects.ObjectContext.<SaveChangesToStoreAsync>d__39.MoveNext()
--- Fin del seguimiento de la pila de la ubicación anterior donde se produjo la excepción ---
   en System.Runtime.CompilerServices.TaskAwaiter.ThrowForNonSuccess(Task task)
   en System.Runtime.CompilerServices.TaskAwaiter.HandleNonSuccessAndDebuggerNotification(Task task)
   en System.Data.Entity.SqlServer.DefaultSqlExecutionStrategy.<ExecuteAsyncImplementation>d__9`1.MoveNext()
--- Fin del seguimiento de la pila de la ubicación anterior donde se produjo la excepción ---
   en System.Runtime.CompilerServices.TaskAwaiter.ThrowForNonSuccess(Task task)
   en System.Runtime.CompilerServices.TaskAwaiter.HandleNonSuccessAndDebuggerNotification(Task task)
   en System.Data.Entity.Core.Objects.ObjectContext.<SaveChangesInternalAsync>d__31.MoveNext()
   --- Fin del seguimiento de la pila de la excepción interna ---
   en DataAccessLayer.Repositories.UserRepository.<Update>d__6.MoveNext() en C:\Users\emoret\source\repos\WebAPIService\DataAccessLayer\Repositories\UserRepository.cs:línea 86
--- Fin del seguimiento de la pila de la ubicación anterior donde se produjo la excepción ---
   en System.Runtime.CompilerServices.TaskAwaiter.ThrowForNonSuccess(Task task)
   en System.Runtime.CompilerServices.TaskAwaiter.HandleNonSuccessAndDebuggerNotification(Task task)
   en System.Runtime.CompilerServices.TaskAwaiter`1.GetResult()
   en DataAccessLayer.UsersData.<Update>d__5.MoveNext() en C:\Users\emoret\source\repos\WebAPIService\DataAccessLayer\UsersData.cs:línea 36
--- Fin del seguimiento de la pila de la ubicación anterior donde se produjo la excepción ---
   en System.Runtime.CompilerServices.TaskAwaiter.ThrowForNonSuccess(Task task)
   en System.Runtime.CompilerServices.TaskAwaiter.HandleNonSuccessAndDebuggerNotification(Task task)
   en System.Runtime.CompilerServices.TaskAwaiter`1.GetResult()
   en BusinessLayer.UserBusiness.<Update>d__7.MoveNext()
--- Fin del seguimiento de la pila de la ubicación anterior donde se produjo la excepción ---
   en System.Runtime.CompilerServices.TaskAwaiter.ThrowForNonSuccess(Task task)
   en System.Runtime.CompilerServices.TaskAwaiter.HandleNonSuccessAndDebuggerNotification(Task task)
   en System.Runtime.CompilerServices.TaskAwaiter`1.GetResult()
   en WebAPIService.Controllers.UsersController.<UpdateUserAsync>d__7.MoveNext() en C:\Users\emoret\source\repos\WebAPIService\WebAPIService\Controllers\UsersController.cs:línea 88
ERROR 2019-04-29 16:17:45,998 25161465ms UsersController        MoveNext           - error in UsersController -> UpdateUserAsync: 
System.NullReferenceException: Referencia a objeto no establecida como instancia de un objeto.
   en DataAccessLayer.Repositories.UserRepository.<Update>d__6.MoveNext() en C:\Users\emoret\source\repos\WebAPIService\DataAccessLayer\Repositories\UserRepository.cs:línea 86
--- Fin del seguimiento de la pila de la ubicación anterior donde se produjo la excepción ---
   en System.Runtime.CompilerServices.TaskAwaiter.ThrowForNonSuccess(Task task)
   en System.Runtime.CompilerServices.TaskAwaiter.HandleNonSuccessAndDebuggerNotification(Task task)
   en System.Runtime.CompilerServices.TaskAwaiter`1.GetResult()
   en DataAccessLayer.UsersData.<Update>d__5.MoveNext() en C:\Users\emoret\source\repos\WebAPIService\DataAccessLayer\UsersData.cs:línea 36
--- Fin del seguimiento de la pila de la ubicación anterior donde se produjo la excepción ---
   en System.Runtime.CompilerServices.TaskAwaiter.ThrowForNonSuccess(Task task)
   en System.Runtime.CompilerServices.TaskAwaiter.HandleNonSuccessAndDebuggerNotification(Task task)
   en System.Runtime.CompilerServices.TaskAwaiter`1.GetResult()
   en BusinessLayer.UserBusiness.<Update>d__7.MoveNext()
--- Fin del seguimiento de la pila de la ubicación anterior donde se produjo la excepción ---
   en System.Runtime.CompilerServices.TaskAwaiter.ThrowForNonSuccess(Task task)
   en System.Runtime.CompilerServices.TaskAwaiter.HandleNonSuccessAndDebuggerNotification(Task task)
   en System.Runtime.CompilerServices.TaskAwaiter`1.GetResult()
   en WebAPIService.Controllers.UsersController.<UpdateUserAsync>d__7.MoveNext() en C:\Users\emoret\source\repos\WebAPIService\WebAPIService\Controllers\UsersController.cs:línea 98
ERROR 2019-04-29 16:17:49,873 25165340ms UsersController        MoveNext           - error in UsersController -> UpdateUserAsync: 
System.NullReferenceException: Referencia a objeto no establecida como instancia de un objeto.
   en DataAccessLayer.Repositories.UserRepository.<Update>d__6.MoveNext() en C:\Users\emoret\source\repos\WebAPIService\DataAccessLayer\Repositories\UserRepository.cs:línea 86
--- Fin del seguimiento de la pila de la ubicación anterior donde se produjo la excepción ---
   en System.Runtime.CompilerServices.TaskAwaiter.ThrowForNonSuccess(Task task)
   en System.Runtime.CompilerServices.TaskAwaiter.HandleNonSuccessAndDebuggerNotification(Task task)
   en System.Runtime.CompilerServices.TaskAwaiter`1.GetResult()
   en DataAccessLayer.UsersData.<Update>d__5.MoveNext() en C:\Users\emoret\source\repos\WebAPIService\DataAccessLayer\UsersData.cs:línea 36
--- Fin del seguimiento de la pila de la ubicación anterior donde se produjo la excepción ---
   en System.Runtime.CompilerServices.TaskAwaiter.ThrowForNonSuccess(Task task)
   en System.Runtime.CompilerServices.TaskAwaiter.HandleNonSuccessAndDebuggerNotification(Task task)
   en System.Runtime.CompilerServices.TaskAwaiter`1.GetResult()
   en BusinessLayer.UserBusiness.<Update>d__7.MoveNext()
--- Fin del seguimiento de la pila de la ubicación anterior donde se produjo la excepción ---
   en System.Runtime.CompilerServices.TaskAwaiter.ThrowForNonSuccess(Task task)
   en System.Runtime.CompilerServices.TaskAwaiter.HandleNonSuccessAndDebuggerNotification(Task task)
   en System.Runtime.CompilerServices.TaskAwaiter`1.GetResult()
   en WebAPIService.Controllers.UsersController.<UpdateUserAsync>d__7.MoveNext() en C:\Users\emoret\source\repos\WebAPIService\WebAPIService\Controllers\UsersController.cs:línea 98
ERROR 2019-04-29 16:19:07,450 25242917ms UsersController        MoveNext           - error in UsersController -> UpdateUserAsync: 
System.NullReferenceException: Referencia a objeto no establecida como instancia de un objeto.
   en DataAccessLayer.Repositories.UserRepository.<Update>d__6.MoveNext() en C:\Users\emoret\source\repos\WebAPIService\DataAccessLayer\Repositories\UserRepository.cs:línea 86
--- Fin del seguimiento de la pila de la ubicación anterior donde se produjo la excepción ---
   en System.Runtime.CompilerServices.TaskAwaiter.ThrowForNonSuccess(Task task)
   en System.Runtime.CompilerServices.TaskAwaiter.HandleNonSuccessAndDebuggerNotification(Task task)
   en System.Runtime.CompilerServices.TaskAwaiter`1.GetResult()
   en DataAccessLayer.UsersData.<Update>d__5.MoveNext() en C:\Users\emoret\source\repos\WebAPIService\DataAccessLayer\UsersData.cs:línea 36
--- Fin del seguimiento de la pila de la ubicación anterior donde se produjo la excepción ---
   en System.Runtime.CompilerServices.TaskAwaiter.ThrowForNonSuccess(Task task)
   en System.Runtime.CompilerServices.TaskAwaiter.HandleNonSuccessAndDebuggerNotification(Task task)
   en System.Runtime.CompilerServices.TaskAwaiter`1.GetResult()
   en BusinessLayer.UserBusiness.<Update>d__7.MoveNext()
--- Fin del seguimiento de la pila de la ubicación anterior donde se produjo la excepción ---
   en System.Runtime.CompilerServices.TaskAwaiter.ThrowForNonSuccess(Task task)
   en System.Runtime.CompilerServices.TaskAwaiter.HandleNonSuccessAndDebuggerNotification(Task task)
   en System.Runtime.CompilerServices.TaskAwaiter`1.GetResult()
   en WebAPIService.Controllers.UsersController.<UpdateUserAsync>d__7.MoveNext() en C:\Users\emoret\source\repos\WebAPIService\WebAPIService\Controllers\UsersController.cs:línea 98
ERROR 2019-04-29 16:21:48,207 25403674ms UsersController        MoveNext           - error in UsersController -> UpdateUserAsync: 
System.NullReferenceException: Referencia a objeto no establecida como instancia de un objeto.
   en DataAccessLayer.Repositories.UserRepository.<Update>d__6.MoveNext() en C:\Users\emoret\source\repos\WebAPIService\DataAccessLayer\Repositories\UserRepository.cs:línea 86
--- Fin del seguimiento de la pila de la ubicación anterior donde se produjo la excepción ---
   en System.Runtime.CompilerServices.TaskAwaiter.ThrowForNonSuccess(Task task)
   en System.Runtime.CompilerServices.TaskAwaiter.HandleNonSuccessAndDebuggerNotification(Task task)
   en System.Runtime.CompilerServices.TaskAwaiter`1.GetResult()
   en DataAccessLayer.UsersData.<Update>d__5.MoveNext() en C:\Users\emoret\source\repos\WebAPIService\DataAccessLayer\UsersData.cs:línea 36
--- Fin del seguimiento de la pila de la ubicación anterior donde se produjo la excepción ---
   en System.Runtime.CompilerServices.TaskAwaiter.ThrowForNonSuccess(Task task)
   en System.Runtime.CompilerServices.TaskAwaiter.HandleNonSuccessAndDebuggerNotification(Task task)
   en System.Runtime.CompilerServices.TaskAwaiter`1.GetResult()
   en BusinessLayer.UserBusiness.<Update>d__7.MoveNext()
--- Fin del seguimiento de la pila de la ubicación anterior donde se produjo la excepción ---
   en System.Runtime.CompilerServices.TaskAwaiter.ThrowForNonSuccess(Task task)
   en System.Runtime.CompilerServices.TaskAwaiter.HandleNonSuccessAndDebuggerNotification(Task task)
   en System.Runtime.CompilerServices.TaskAwaiter`1.GetResult()
   en WebAPIService.Controllers.UsersController.<UpdateUserAsync>d__7.MoveNext() en C:\Users\emoret\source\repos\WebAPIService\WebAPIService\Controllers\UsersController.cs:línea 98
ERROR 2019-04-29 16:22:18,968 25434434ms UsersController        MoveNext           - error in UsersController -> UpdateUserAsync: 
System.NullReferenceException: Referencia a objeto no establecida como instancia de un objeto.
   en DataAccessLayer.Repositories.UserRepository.<Update>d__6.MoveNext() en C:\Users\emoret\source\repos\WebAPIService\DataAccessLayer\Repositories\UserRepository.cs:línea 86
--- Fin del seguimiento de la pila de la ubicación anterior donde se produjo la excepción ---
   en System.Runtime.CompilerServices.TaskAwaiter.ThrowForNonSuccess(Task task)
   en System.Runtime.CompilerServices.TaskAwaiter.HandleNonSuccessAndDebuggerNotification(Task task)
   en System.Runtime.CompilerServices.TaskAwaiter`1.GetResult()
   en DataAccessLayer.UsersData.<Update>d__5.MoveNext() en C:\Users\emoret\source\repos\WebAPIService\DataAccessLayer\UsersData.cs:línea 36
--- Fin del seguimiento de la pila de la ubicación anterior donde se produjo la excepción ---
   en System.Runtime.CompilerServices.TaskAwaiter.ThrowForNonSuccess(Task task)
   en System.Runtime.CompilerServices.TaskAwaiter.HandleNonSuccessAndDebuggerNotification(Task task)
   en System.Runtime.CompilerServices.TaskAwaiter`1.GetResult()
   en BusinessLayer.UserBusiness.<Update>d__7.MoveNext()
--- Fin del seguimiento de la pila de la ubicación anterior donde se produjo la excepción ---
   en System.Runtime.CompilerServices.TaskAwaiter.ThrowForNonSuccess(Task task)
   en System.Runtime.CompilerServices.TaskAwaiter.HandleNonSuccessAndDebuggerNotification(Task task)
   en System.Runtime.CompilerServices.TaskAwaiter`1.GetResult()
   en WebAPIService.Controllers.UsersController.<UpdateUserAsync>d__7.MoveNext() en C:\Users\emoret\source\repos\WebAPIService\WebAPIService\Controllers\UsersController.cs:línea 98
ERROR 2019-05-01 21:21:11,261 61008ms UsersController        MoveNext           - error in UsersController -> UpdateUserAsync: 
System.InvalidOperationException: The entity type List`1 is not part of the model for the current context.
   en DataAccessLayer.Repositories.UserRepository.<Update>d__6.MoveNext() en C:\Users\emoret\source\repos\WebAPIService\DataAccessLayer\Repositories\UserRepository.cs:línea 89
--- Fin del seguimiento de la pila de la ubicación anterior donde se produjo la excepción ---
   en System.Runtime.CompilerServices.TaskAwaiter.ThrowForNonSuccess(Task task)
   en System.Runtime.CompilerServices.TaskAwaiter.HandleNonSuccessAndDebuggerNotification(Task task)
   en System.Runtime.CompilerServices.TaskAwaiter`1.GetResult()
   en DataAccessLayer.UsersData.<Update>d__5.MoveNext() en C:\Users\emoret\source\repos\WebAPIService\DataAccessLayer\UsersData.cs:línea 36
--- Fin del seguimiento de la pila de la ubicación anterior donde se produjo la excepción ---
   en System.Runtime.CompilerServices.TaskAwaiter.ThrowForNonSuccess(Task task)
   en System.Runtime.CompilerServices.TaskAwaiter.HandleNonSuccessAndDebuggerNotification(Task task)
   en System.Runtime.CompilerServices.TaskAwaiter`1.GetResult()
   en BusinessLayer.UserBusiness.<Update>d__7.MoveNext()
--- Fin del seguimiento de la pila de la ubicación anterior donde se produjo la excepción ---
   en System.Runtime.CompilerServices.TaskAwaiter.ThrowForNonSuccess(Task task)
   en System.Runtime.CompilerServices.TaskAwaiter.HandleNonSuccessAndDebuggerNotification(Task task)
   en System.Runtime.CompilerServices.TaskAwaiter`1.GetResult()
   en WebAPIService.Controllers.UsersController.<UpdateUserAsync>d__7.MoveNext() en C:\Users\emoret\source\repos\WebAPIService\WebAPIService\Controllers\UsersController.cs:línea 97
ERROR 2019-05-01 21:21:15,404 65151ms UsersController        MoveNext           - error in UsersController -> UpdateUserAsync: 
System.InvalidOperationException: The entity type List`1 is not part of the model for the current context.
   en DataAccessLayer.Repositories.UserRepository.<Update>d__6.MoveNext() en C:\Users\emoret\source\repos\WebAPIService\DataAccessLayer\Repositories\UserRepository.cs:línea 89
--- Fin del seguimiento de la pila de la ubicación anterior donde se produjo la excepción ---
   en System.Runtime.CompilerServices.TaskAwaiter.ThrowForNonSuccess(Task task)
   en System.Runtime.CompilerServices.TaskAwaiter.HandleNonSuccessAndDebuggerNotification(Task task)
   en System.Runtime.CompilerServices.TaskAwaiter`1.GetResult()
   en DataAccessLayer.UsersData.<Update>d__5.MoveNext() en C:\Users\emoret\source\repos\WebAPIService\DataAccessLayer\UsersData.cs:línea 36
--- Fin del seguimiento de la pila de la ubicación anterior donde se produjo la excepción ---
   en System.Runtime.CompilerServices.TaskAwaiter.ThrowForNonSuccess(Task task)
   en System.Runtime.CompilerServices.TaskAwaiter.HandleNonSuccessAndDebuggerNotification(Task task)
   en System.Runtime.CompilerServices.TaskAwaiter`1.GetResult()
   en BusinessLayer.UserBusiness.<Update>d__7.MoveNext()
--- Fin del seguimiento de la pila de la ubicación anterior donde se produjo la excepción ---
   en System.Runtime.CompilerServices.TaskAwaiter.ThrowForNonSuccess(Task task)
   en System.Runtime.CompilerServices.TaskAwaiter.HandleNonSuccessAndDebuggerNotification(Task task)
   en System.Runtime.CompilerServices.TaskAwaiter`1.GetResult()
   en WebAPIService.Controllers.UsersController.<UpdateUserAsync>d__7.MoveNext() en C:\Users\emoret\source\repos\WebAPIService\WebAPIService\Controllers\UsersController.cs:línea 97
ERROR 2019-05-01 22:21:31,919 48636ms UsersController        MoveNext           - error in UsersController -> UpdateUserAsync: 
System.InvalidOperationException: Reload cannot be used for entities in the Added state.
   en DataAccessLayer.Repositories.UserRepository.<Update>d__6.MoveNext() en C:\Users\emoret\source\repos\WebAPIService\DataAccessLayer\Repositories\UserRepository.cs:línea 93
--- Fin del seguimiento de la pila de la ubicación anterior donde se produjo la excepción ---
   en System.Runtime.CompilerServices.TaskAwaiter.ThrowForNonSuccess(Task task)
   en System.Runtime.CompilerServices.TaskAwaiter.HandleNonSuccessAndDebuggerNotification(Task task)
   en System.Runtime.CompilerServices.TaskAwaiter`1.GetResult()
   en DataAccessLayer.UsersData.<Update>d__5.MoveNext() en C:\Users\emoret\source\repos\WebAPIService\DataAccessLayer\UsersData.cs:línea 36
--- Fin del seguimiento de la pila de la ubicación anterior donde se produjo la excepción ---
   en System.Runtime.CompilerServices.TaskAwaiter.ThrowForNonSuccess(Task task)
   en System.Runtime.CompilerServices.TaskAwaiter.HandleNonSuccessAndDebuggerNotification(Task task)
   en System.Runtime.CompilerServices.TaskAwaiter`1.GetResult()
   en BusinessLayer.UserBusiness.<Update>d__7.MoveNext()
--- Fin del seguimiento de la pila de la ubicación anterior donde se produjo la excepción ---
   en System.Runtime.CompilerServices.TaskAwaiter.ThrowForNonSuccess(Task task)
   en System.Runtime.CompilerServices.TaskAwaiter.HandleNonSuccessAndDebuggerNotification(Task task)
   en System.Runtime.CompilerServices.TaskAwaiter`1.GetResult()
   en WebAPIService.Controllers.UsersController.<UpdateUserAsync>d__7.MoveNext() en C:\Users\emoret\source\repos\WebAPIService\WebAPIService\Controllers\UsersController.cs:línea 97
ERROR 2019-05-02 09:40:07,757 25720ms UsersController        MoveNext           - error in UsersController -> GetUserById: 
System.ObjectDisposedException: The ObjectContext instance has been disposed and can no longer be used for operations that require a connection.
   en System.Data.Entity.Core.Objects.ObjectContext.get_Connection()
   en System.Data.Entity.Core.Objects.ObjectQuery`1.GetResults(Nullable`1 forMergeOption)
   en System.Data.Entity.Core.Objects.ObjectQuery`1.Execute(MergeOption mergeOption)
   en System.Data.Entity.Core.Objects.DataClasses.EntityCollection`1.Load(List`1 collection, MergeOption mergeOption)
   en System.Data.Entity.Core.Objects.DataClasses.EntityCollection`1.Load(MergeOption mergeOption)
   en System.Data.Entity.Core.Objects.DataClasses.RelatedEnd.DeferredLoad()
   en System.Data.Entity.Core.Objects.Internal.LazyLoadBehavior.LoadProperty[TItem](TItem propertyValue, String relationshipName, String targetRoleName, Boolean mustBeNull, Object wrapperObject)
   en System.Data.Entity.Core.Objects.Internal.LazyLoadBehavior.<>c__DisplayClass7`2.<GetInterceptorDelegate>b__1(TProxy proxy, TItem item)
   en System.Data.Entity.DynamicProxies.Users_D14047590A8F48DF68387E80279D4223F77FA0EE6558BACC53EB074A88A01CBA.get_UsersRoles()
   en BusinessLayer.Mapper.FactoryMapper.MapToDtoWithPassword(Users user)
   en BusinessLayer.UserBusiness.<GetByIdAsync>d__4.MoveNext()
--- Fin del seguimiento de la pila de la ubicación anterior donde se produjo la excepción ---
   en System.Runtime.CompilerServices.TaskAwaiter.ThrowForNonSuccess(Task task)
   en System.Runtime.CompilerServices.TaskAwaiter.HandleNonSuccessAndDebuggerNotification(Task task)
   en System.Runtime.CompilerServices.TaskAwaiter`1.GetResult()
   en WebAPIService.Controllers.UsersController.<GetUserById>d__5.MoveNext() en C:\Users\emoret\source\repos\WebAPIService\WebAPIService\Controllers\UsersController.cs:línea 55
ERROR 2019-05-02 09:40:19,778 37741ms UsersController        MoveNext           - error in UsersController -> GetUserById: 
System.ObjectDisposedException: The ObjectContext instance has been disposed and can no longer be used for operations that require a connection.
   en System.Data.Entity.Core.Objects.ObjectContext.get_Connection()
   en System.Data.Entity.Core.Objects.ObjectQuery`1.GetResults(Nullable`1 forMergeOption)
   en System.Data.Entity.Core.Objects.ObjectQuery`1.Execute(MergeOption mergeOption)
   en System.Data.Entity.Core.Objects.DataClasses.EntityReference`1.Load(MergeOption mergeOption)
   en System.Data.Entity.Core.Objects.DataClasses.RelatedEnd.DeferredLoad()
   en System.Data.Entity.Core.Objects.Internal.LazyLoadBehavior.LoadProperty[TItem](TItem propertyValue, String relationshipName, String targetRoleName, Boolean mustBeNull, Object wrapperObject)
   en System.Data.Entity.Core.Objects.Internal.LazyLoadBehavior.<>c__DisplayClass7`2.<GetInterceptorDelegate>b__2(TProxy proxy, TItem item)
   en System.Data.Entity.DynamicProxies.UsersRoles_425F43F138CF6E66153D578D6696C863F9757661BE6B3478340CD2F999977A27.get_Roles()
   en BusinessLayer.Mapper.FactoryMapper.<>c__DisplayClass3_0.<MapToDto>b__0(UsersRoles role)
   en System.Collections.Generic.List`1.ForEach(Action`1 action)
   en BusinessLayer.Mapper.FactoryMapper.MapToDto(List`1 roles)
   en BusinessLayer.Mapper.FactoryMapper.MapToDtoWithPassword(Users user)
   en BusinessLayer.UserBusiness.<GetByIdAsync>d__4.MoveNext()
--- Fin del seguimiento de la pila de la ubicación anterior donde se produjo la excepción ---
   en System.Runtime.CompilerServices.TaskAwaiter.ThrowForNonSuccess(Task task)
   en System.Runtime.CompilerServices.TaskAwaiter.HandleNonSuccessAndDebuggerNotification(Task task)
   en System.Runtime.CompilerServices.TaskAwaiter`1.GetResult()
   en WebAPIService.Controllers.UsersController.<GetUserById>d__5.MoveNext() en C:\Users\emoret\source\repos\WebAPIService\WebAPIService\Controllers\UsersController.cs:línea 55
ERROR 2019-05-02 09:40:49,595 67558ms UsersController        MoveNext           - error in UsersController -> GetUserById: 
System.ObjectDisposedException: The ObjectContext instance has been disposed and can no longer be used for operations that require a connection.
   en System.Data.Entity.Core.Objects.ObjectContext.get_Connection()
   en System.Data.Entity.Core.Objects.ObjectQuery`1.GetResults(Nullable`1 forMergeOption)
   en System.Data.Entity.Core.Objects.ObjectQuery`1.Execute(MergeOption mergeOption)
   en System.Data.Entity.Core.Objects.DataClasses.EntityCollection`1.Load(List`1 collection, MergeOption mergeOption)
   en System.Data.Entity.Core.Objects.DataClasses.EntityCollection`1.Load(MergeOption mergeOption)
   en System.Data.Entity.Core.Objects.DataClasses.RelatedEnd.DeferredLoad()
   en System.Data.Entity.Core.Objects.Internal.LazyLoadBehavior.LoadProperty[TItem](TItem propertyValue, String relationshipName, String targetRoleName, Boolean mustBeNull, Object wrapperObject)
   en System.Data.Entity.Core.Objects.Internal.LazyLoadBehavior.<>c__DisplayClass7`2.<GetInterceptorDelegate>b__1(TProxy proxy, TItem item)
   en System.Data.Entity.DynamicProxies.Users_D14047590A8F48DF68387E80279D4223F77FA0EE6558BACC53EB074A88A01CBA.get_UsersRoles()
   en BusinessLayer.Mapper.FactoryMapper.MapToDtoWithPassword(Users user)
   en BusinessLayer.UserBusiness.<GetByIdAsync>d__4.MoveNext()
--- Fin del seguimiento de la pila de la ubicación anterior donde se produjo la excepción ---
   en System.Runtime.CompilerServices.TaskAwaiter.ThrowForNonSuccess(Task task)
   en System.Runtime.CompilerServices.TaskAwaiter.HandleNonSuccessAndDebuggerNotification(Task task)
   en System.Runtime.CompilerServices.TaskAwaiter`1.GetResult()
   en WebAPIService.Controllers.UsersController.<GetUserById>d__5.MoveNext() en C:\Users\emoret\source\repos\WebAPIService\WebAPIService\Controllers\UsersController.cs:línea 55
ERROR 2019-05-02 09:53:50,971 31233ms UsersController        MoveNext           - error in UsersController -> GetUserById: 
System.ObjectDisposedException: The ObjectContext instance has been disposed and can no longer be used for operations that require a connection.
   en System.Data.Entity.Core.Objects.ObjectContext.get_Connection()
   en System.Data.Entity.Core.Objects.ObjectQuery`1.GetResults(Nullable`1 forMergeOption)
   en System.Data.Entity.Core.Objects.ObjectQuery`1.Execute(MergeOption mergeOption)
   en System.Data.Entity.Core.Objects.DataClasses.EntityReference`1.Load(MergeOption mergeOption)
   en System.Data.Entity.Core.Objects.DataClasses.RelatedEnd.DeferredLoad()
   en System.Data.Entity.Core.Objects.Internal.LazyLoadBehavior.LoadProperty[TItem](TItem propertyValue, String relationshipName, String targetRoleName, Boolean mustBeNull, Object wrapperObject)
   en System.Data.Entity.Core.Objects.Internal.LazyLoadBehavior.<>c__DisplayClass7`2.<GetInterceptorDelegate>b__2(TProxy proxy, TItem item)
   en System.Data.Entity.DynamicProxies.UsersRoles_425F43F138CF6E66153D578D6696C863F9757661BE6B3478340CD2F999977A27.get_Roles()
   en BusinessLayer.Mapper.FactoryMapper.<>c__DisplayClass3_0.<MapToDto>b__0(UsersRoles role)
   en System.Collections.Generic.List`1.ForEach(Action`1 action)
   en BusinessLayer.Mapper.FactoryMapper.MapToDto(List`1 roles)
   en BusinessLayer.Mapper.FactoryMapper.MapToDtoWithPassword(Users user)
   en BusinessLayer.UserBusiness.<GetByIdAsync>d__4.MoveNext()
--- Fin del seguimiento de la pila de la ubicación anterior donde se produjo la excepción ---
   en System.Runtime.CompilerServices.TaskAwaiter.ThrowForNonSuccess(Task task)
   en System.Runtime.CompilerServices.TaskAwaiter.HandleNonSuccessAndDebuggerNotification(Task task)
   en System.Runtime.CompilerServices.TaskAwaiter`1.GetResult()
   en WebAPIService.Controllers.UsersController.<GetUserById>d__5.MoveNext() en C:\Users\emoret\source\repos\WebAPIService\WebAPIService\Controllers\UsersController.cs:línea 55
ERROR 2019-05-02 09:59:45,573 36145ms UsersController        MoveNext           - error in UsersController -> GetUserById: 
System.ObjectDisposedException: The ObjectContext instance has been disposed and can no longer be used for operations that require a connection.
   en System.Data.Entity.Core.Objects.ObjectContext.get_Connection()
   en System.Data.Entity.Core.Objects.ObjectQuery`1.GetResults(Nullable`1 forMergeOption)
   en System.Data.Entity.Core.Objects.ObjectQuery`1.Execute(MergeOption mergeOption)
   en System.Data.Entity.Core.Objects.DataClasses.EntityReference`1.Load(MergeOption mergeOption)
   en System.Data.Entity.Core.Objects.DataClasses.RelatedEnd.DeferredLoad()
   en System.Data.Entity.Core.Objects.Internal.LazyLoadBehavior.LoadProperty[TItem](TItem propertyValue, String relationshipName, String targetRoleName, Boolean mustBeNull, Object wrapperObject)
   en System.Data.Entity.Core.Objects.Internal.LazyLoadBehavior.<>c__DisplayClass7`2.<GetInterceptorDelegate>b__2(TProxy proxy, TItem item)
   en System.Data.Entity.DynamicProxies.UsersRoles_425F43F138CF6E66153D578D6696C863F9757661BE6B3478340CD2F999977A27.get_Roles()
   en BusinessLayer.Mapper.FactoryMapper.<>c__DisplayClass3_0.<MapToDto>b__0(UsersRoles role)
   en System.Collections.Generic.List`1.ForEach(Action`1 action)
   en BusinessLayer.Mapper.FactoryMapper.MapToDto(List`1 roles)
   en BusinessLayer.Mapper.FactoryMapper.MapToDtoWithPassword(Users user)
   en BusinessLayer.UserBusiness.<GetByIdAsync>d__4.MoveNext()
--- Fin del seguimiento de la pila de la ubicación anterior donde se produjo la excepción ---
   en System.Runtime.CompilerServices.TaskAwaiter.ThrowForNonSuccess(Task task)
   en System.Runtime.CompilerServices.TaskAwaiter.HandleNonSuccessAndDebuggerNotification(Task task)
   en System.Runtime.CompilerServices.TaskAwaiter`1.GetResult()
   en WebAPIService.Controllers.UsersController.<GetUserById>d__5.MoveNext() en C:\Users\emoret\source\repos\WebAPIService\WebAPIService\Controllers\UsersController.cs:línea 55
ERROR 2019-05-02 10:00:04,553 55125ms UsersController        MoveNext           - error in UsersController -> GetUserById: 
System.ObjectDisposedException: The ObjectContext instance has been disposed and can no longer be used for operations that require a connection.
   en System.Data.Entity.Core.Objects.ObjectContext.get_Connection()
   en System.Data.Entity.Core.Objects.ObjectQuery`1.GetResults(Nullable`1 forMergeOption)
   en System.Data.Entity.Core.Objects.ObjectQuery`1.Execute(MergeOption mergeOption)
   en System.Data.Entity.Core.Objects.DataClasses.EntityReference`1.Load(MergeOption mergeOption)
   en System.Data.Entity.Core.Objects.DataClasses.RelatedEnd.DeferredLoad()
   en System.Data.Entity.Core.Objects.Internal.LazyLoadBehavior.LoadProperty[TItem](TItem propertyValue, String relationshipName, String targetRoleName, Boolean mustBeNull, Object wrapperObject)
   en System.Data.Entity.Core.Objects.Internal.LazyLoadBehavior.<>c__DisplayClass7`2.<GetInterceptorDelegate>b__2(TProxy proxy, TItem item)
   en System.Data.Entity.DynamicProxies.UsersRoles_425F43F138CF6E66153D578D6696C863F9757661BE6B3478340CD2F999977A27.get_Roles()
   en BusinessLayer.Mapper.FactoryMapper.<>c__DisplayClass3_0.<MapToDto>b__0(UsersRoles role)
   en System.Collections.Generic.List`1.ForEach(Action`1 action)
   en BusinessLayer.Mapper.FactoryMapper.MapToDto(List`1 roles)
   en BusinessLayer.Mapper.FactoryMapper.MapToDtoWithPassword(Users user)
   en BusinessLayer.UserBusiness.<GetByIdAsync>d__4.MoveNext()
--- Fin del seguimiento de la pila de la ubicación anterior donde se produjo la excepción ---
   en System.Runtime.CompilerServices.TaskAwaiter.ThrowForNonSuccess(Task task)
   en System.Runtime.CompilerServices.TaskAwaiter.HandleNonSuccessAndDebuggerNotification(Task task)
   en System.Runtime.CompilerServices.TaskAwaiter`1.GetResult()
   en WebAPIService.Controllers.UsersController.<GetUserById>d__5.MoveNext() en C:\Users\emoret\source\repos\WebAPIService\WebAPIService\Controllers\UsersController.cs:línea 55
ERROR 2019-05-02 10:00:14,054 64626ms UsersController        MoveNext           - error in UsersController -> GetUserById: 
System.ObjectDisposedException: The ObjectContext instance has been disposed and can no longer be used for operations that require a connection.
   en System.Data.Entity.Core.Objects.ObjectContext.get_Connection()
   en System.Data.Entity.Core.Objects.ObjectQuery`1.GetResults(Nullable`1 forMergeOption)
   en System.Data.Entity.Core.Objects.ObjectQuery`1.Execute(MergeOption mergeOption)
   en System.Data.Entity.Core.Objects.DataClasses.EntityReference`1.Load(MergeOption mergeOption)
   en System.Data.Entity.Core.Objects.DataClasses.RelatedEnd.DeferredLoad()
   en System.Data.Entity.Core.Objects.Internal.LazyLoadBehavior.LoadProperty[TItem](TItem propertyValue, String relationshipName, String targetRoleName, Boolean mustBeNull, Object wrapperObject)
   en System.Data.Entity.Core.Objects.Internal.LazyLoadBehavior.<>c__DisplayClass7`2.<GetInterceptorDelegate>b__2(TProxy proxy, TItem item)
   en System.Data.Entity.DynamicProxies.UsersRoles_425F43F138CF6E66153D578D6696C863F9757661BE6B3478340CD2F999977A27.get_Roles()
   en BusinessLayer.Mapper.FactoryMapper.<>c__DisplayClass3_0.<MapToDto>b__0(UsersRoles role)
   en System.Collections.Generic.List`1.ForEach(Action`1 action)
   en BusinessLayer.Mapper.FactoryMapper.MapToDto(List`1 roles)
   en BusinessLayer.Mapper.FactoryMapper.MapToDtoWithPassword(Users user)
   en BusinessLayer.UserBusiness.<GetByIdAsync>d__4.MoveNext()
--- Fin del seguimiento de la pila de la ubicación anterior donde se produjo la excepción ---
   en System.Runtime.CompilerServices.TaskAwaiter.ThrowForNonSuccess(Task task)
   en System.Runtime.CompilerServices.TaskAwaiter.HandleNonSuccessAndDebuggerNotification(Task task)
   en System.Runtime.CompilerServices.TaskAwaiter`1.GetResult()
   en WebAPIService.Controllers.UsersController.<GetUserById>d__5.MoveNext() en C:\Users\emoret\source\repos\WebAPIService\WebAPIService\Controllers\UsersController.cs:línea 55
ERROR 2019-05-02 10:00:27,047 77619ms UsersController        MoveNext           - error in UsersController -> GetUserById: 
System.ObjectDisposedException: The ObjectContext instance has been disposed and can no longer be used for operations that require a connection.
   en System.Data.Entity.Core.Objects.ObjectContext.get_Connection()
   en System.Data.Entity.Core.Objects.ObjectQuery`1.GetResults(Nullable`1 forMergeOption)
   en System.Data.Entity.Core.Objects.ObjectQuery`1.Execute(MergeOption mergeOption)
   en System.Data.Entity.Core.Objects.DataClasses.EntityReference`1.Load(MergeOption mergeOption)
   en System.Data.Entity.Core.Objects.DataClasses.RelatedEnd.DeferredLoad()
   en System.Data.Entity.Core.Objects.Internal.LazyLoadBehavior.LoadProperty[TItem](TItem propertyValue, String relationshipName, String targetRoleName, Boolean mustBeNull, Object wrapperObject)
   en System.Data.Entity.Core.Objects.Internal.LazyLoadBehavior.<>c__DisplayClass7`2.<GetInterceptorDelegate>b__2(TProxy proxy, TItem item)
   en System.Data.Entity.DynamicProxies.UsersRoles_425F43F138CF6E66153D578D6696C863F9757661BE6B3478340CD2F999977A27.get_Roles()
   en BusinessLayer.Mapper.FactoryMapper.<>c__DisplayClass3_0.<MapToDto>b__0(UsersRoles role)
   en System.Collections.Generic.List`1.ForEach(Action`1 action)
   en BusinessLayer.Mapper.FactoryMapper.MapToDto(List`1 roles)
   en BusinessLayer.Mapper.FactoryMapper.MapToDtoWithPassword(Users user)
   en BusinessLayer.UserBusiness.<GetByIdAsync>d__4.MoveNext()
--- Fin del seguimiento de la pila de la ubicación anterior donde se produjo la excepción ---
   en System.Runtime.CompilerServices.TaskAwaiter.ThrowForNonSuccess(Task task)
   en System.Runtime.CompilerServices.TaskAwaiter.HandleNonSuccessAndDebuggerNotification(Task task)
   en System.Runtime.CompilerServices.TaskAwaiter`1.GetResult()
   en WebAPIService.Controllers.UsersController.<GetUserById>d__5.MoveNext() en C:\Users\emoret\source\repos\WebAPIService\WebAPIService\Controllers\UsersController.cs:línea 55
ERROR 2019-05-02 10:43:28,514 35763ms UsersController        MoveNext           - error in UsersController -> GetAllUsersAsync: 
System.ObjectDisposedException: The ObjectContext instance has been disposed and can no longer be used for operations that require a connection.
   en System.Data.Entity.Core.Objects.ObjectContext.get_Connection()
   en System.Data.Entity.Core.Objects.ObjectQuery`1.GetResults(Nullable`1 forMergeOption)
   en System.Data.Entity.Core.Objects.ObjectQuery`1.Execute(MergeOption mergeOption)
   en System.Data.Entity.Core.Objects.DataClasses.EntityCollection`1.Load(List`1 collection, MergeOption mergeOption)
   en System.Data.Entity.Core.Objects.DataClasses.EntityCollection`1.Load(MergeOption mergeOption)
   en System.Data.Entity.Core.Objects.DataClasses.RelatedEnd.DeferredLoad()
   en System.Data.Entity.Core.Objects.Internal.LazyLoadBehavior.LoadProperty[TItem](TItem propertyValue, String relationshipName, String targetRoleName, Boolean mustBeNull, Object wrapperObject)
   en System.Data.Entity.Core.Objects.Internal.LazyLoadBehavior.<>c__DisplayClass7`2.<GetInterceptorDelegate>b__1(TProxy proxy, TItem item)
   en System.Data.Entity.DynamicProxies.Users_D14047590A8F48DF68387E80279D4223F77FA0EE6558BACC53EB074A88A01CBA.get_UsersRoles()
   en BusinessLayer.Mapper.FactoryMapper.<>c__DisplayClass2_0.<MapToDto>b__0(Users user)
   en System.Collections.Generic.List`1.ForEach(Action`1 action)
   en BusinessLayer.Mapper.FactoryMapper.MapToDto(List`1 users)
   en BusinessLayer.UserBusiness.<GetAllUsersAsync>d__3.MoveNext()
--- Fin del seguimiento de la pila de la ubicación anterior donde se produjo la excepción ---
   en System.Runtime.CompilerServices.TaskAwaiter.ThrowForNonSuccess(Task task)
   en System.Runtime.CompilerServices.TaskAwaiter.HandleNonSuccessAndDebuggerNotification(Task task)
   en System.Runtime.CompilerServices.TaskAwaiter`1.GetResult()
   en WebAPIService.Controllers.UsersController.<GetAllUsers>d__4.MoveNext() en C:\Users\emoret\source\repos\WebAPIService\WebAPIService\Controllers\UsersController.cs:línea 39
ERROR 2019-05-02 10:43:34,346 41595ms UsersController        MoveNext           - error in UsersController -> GetAllUsersAsync: 
System.ObjectDisposedException: The ObjectContext instance has been disposed and can no longer be used for operations that require a connection.
   en System.Data.Entity.Core.Objects.ObjectContext.get_Connection()
   en System.Data.Entity.Core.Objects.ObjectQuery`1.GetResults(Nullable`1 forMergeOption)
   en System.Data.Entity.Core.Objects.ObjectQuery`1.Execute(MergeOption mergeOption)
   en System.Data.Entity.Core.Objects.DataClasses.EntityCollection`1.Load(List`1 collection, MergeOption mergeOption)
   en System.Data.Entity.Core.Objects.DataClasses.EntityCollection`1.Load(MergeOption mergeOption)
   en System.Data.Entity.Core.Objects.DataClasses.RelatedEnd.DeferredLoad()
   en System.Data.Entity.Core.Objects.Internal.LazyLoadBehavior.LoadProperty[TItem](TItem propertyValue, String relationshipName, String targetRoleName, Boolean mustBeNull, Object wrapperObject)
   en System.Data.Entity.Core.Objects.Internal.LazyLoadBehavior.<>c__DisplayClass7`2.<GetInterceptorDelegate>b__1(TProxy proxy, TItem item)
   en System.Data.Entity.DynamicProxies.Users_D14047590A8F48DF68387E80279D4223F77FA0EE6558BACC53EB074A88A01CBA.get_UsersRoles()
   en BusinessLayer.Mapper.FactoryMapper.<>c__DisplayClass2_0.<MapToDto>b__0(Users user)
   en System.Collections.Generic.List`1.ForEach(Action`1 action)
   en BusinessLayer.Mapper.FactoryMapper.MapToDto(List`1 users)
   en BusinessLayer.UserBusiness.<GetAllUsersAsync>d__3.MoveNext()
--- Fin del seguimiento de la pila de la ubicación anterior donde se produjo la excepción ---
   en System.Runtime.CompilerServices.TaskAwaiter.ThrowForNonSuccess(Task task)
   en System.Runtime.CompilerServices.TaskAwaiter.HandleNonSuccessAndDebuggerNotification(Task task)
   en System.Runtime.CompilerServices.TaskAwaiter`1.GetResult()
   en WebAPIService.Controllers.UsersController.<GetAllUsers>d__4.MoveNext() en C:\Users\emoret\source\repos\WebAPIService\WebAPIService\Controllers\UsersController.cs:línea 39
ERROR 2019-05-02 10:43:52,087 59335ms UsersController        MoveNext           - error in UsersController -> GetAllUsersAsync: 
System.ObjectDisposedException: The ObjectContext instance has been disposed and can no longer be used for operations that require a connection.
   en System.Data.Entity.Core.Objects.ObjectContext.get_Connection()
   en System.Data.Entity.Core.Objects.ObjectQuery`1.GetResults(Nullable`1 forMergeOption)
   en System.Data.Entity.Core.Objects.ObjectQuery`1.Execute(MergeOption mergeOption)
   en System.Data.Entity.Core.Objects.DataClasses.EntityCollection`1.Load(List`1 collection, MergeOption mergeOption)
   en System.Data.Entity.Core.Objects.DataClasses.EntityCollection`1.Load(MergeOption mergeOption)
   en System.Data.Entity.Core.Objects.DataClasses.RelatedEnd.DeferredLoad()
   en System.Data.Entity.Core.Objects.Internal.LazyLoadBehavior.LoadProperty[TItem](TItem propertyValue, String relationshipName, String targetRoleName, Boolean mustBeNull, Object wrapperObject)
   en System.Data.Entity.Core.Objects.Internal.LazyLoadBehavior.<>c__DisplayClass7`2.<GetInterceptorDelegate>b__1(TProxy proxy, TItem item)
   en System.Data.Entity.DynamicProxies.Users_D14047590A8F48DF68387E80279D4223F77FA0EE6558BACC53EB074A88A01CBA.get_UsersRoles()
   en BusinessLayer.Mapper.FactoryMapper.<>c__DisplayClass2_0.<MapToDto>b__0(Users user)
   en System.Collections.Generic.List`1.ForEach(Action`1 action)
   en BusinessLayer.Mapper.FactoryMapper.MapToDto(List`1 users)
   en BusinessLayer.UserBusiness.<GetAllUsersAsync>d__3.MoveNext()
--- Fin del seguimiento de la pila de la ubicación anterior donde se produjo la excepción ---
   en System.Runtime.CompilerServices.TaskAwaiter.ThrowForNonSuccess(Task task)
   en System.Runtime.CompilerServices.TaskAwaiter.HandleNonSuccessAndDebuggerNotification(Task task)
   en System.Runtime.CompilerServices.TaskAwaiter`1.GetResult()
   en WebAPIService.Controllers.UsersController.<GetAllUsers>d__4.MoveNext() en C:\Users\emoret\source\repos\WebAPIService\WebAPIService\Controllers\UsersController.cs:línea 39
ERROR 2019-05-02 10:43:55,209 62458ms UsersController        MoveNext           - error in UsersController -> GetAllUsersAsync: 
System.ObjectDisposedException: The ObjectContext instance has been disposed and can no longer be used for operations that require a connection.
   en System.Data.Entity.Core.Objects.ObjectContext.get_Connection()
   en System.Data.Entity.Core.Objects.ObjectQuery`1.GetResults(Nullable`1 forMergeOption)
   en System.Data.Entity.Core.Objects.ObjectQuery`1.Execute(MergeOption mergeOption)
   en System.Data.Entity.Core.Objects.DataClasses.EntityCollection`1.Load(List`1 collection, MergeOption mergeOption)
   en System.Data.Entity.Core.Objects.DataClasses.EntityCollection`1.Load(MergeOption mergeOption)
   en System.Data.Entity.Core.Objects.DataClasses.RelatedEnd.DeferredLoad()
   en System.Data.Entity.Core.Objects.Internal.LazyLoadBehavior.LoadProperty[TItem](TItem propertyValue, String relationshipName, String targetRoleName, Boolean mustBeNull, Object wrapperObject)
   en System.Data.Entity.Core.Objects.Internal.LazyLoadBehavior.<>c__DisplayClass7`2.<GetInterceptorDelegate>b__1(TProxy proxy, TItem item)
   en System.Data.Entity.DynamicProxies.Users_D14047590A8F48DF68387E80279D4223F77FA0EE6558BACC53EB074A88A01CBA.get_UsersRoles()
   en BusinessLayer.Mapper.FactoryMapper.<>c__DisplayClass2_0.<MapToDto>b__0(Users user)
   en System.Collections.Generic.List`1.ForEach(Action`1 action)
   en BusinessLayer.Mapper.FactoryMapper.MapToDto(List`1 users)
   en BusinessLayer.UserBusiness.<GetAllUsersAsync>d__3.MoveNext()
--- Fin del seguimiento de la pila de la ubicación anterior donde se produjo la excepción ---
   en System.Runtime.CompilerServices.TaskAwaiter.ThrowForNonSuccess(Task task)
   en System.Runtime.CompilerServices.TaskAwaiter.HandleNonSuccessAndDebuggerNotification(Task task)
   en System.Runtime.CompilerServices.TaskAwaiter`1.GetResult()
   en WebAPIService.Controllers.UsersController.<GetAllUsers>d__4.MoveNext() en C:\Users\emoret\source\repos\WebAPIService\WebAPIService\Controllers\UsersController.cs:línea 39
ERROR 2019-05-02 10:44:45,612 112861ms UsersController        MoveNext           - error in UsersController -> GetAllUsersAsync: 
System.ObjectDisposedException: The ObjectContext instance has been disposed and can no longer be used for operations that require a connection.
   en System.Data.Entity.Core.Objects.ObjectContext.get_Connection()
   en System.Data.Entity.Core.Objects.ObjectQuery`1.GetResults(Nullable`1 forMergeOption)
   en System.Data.Entity.Core.Objects.ObjectQuery`1.Execute(MergeOption mergeOption)
   en System.Data.Entity.Core.Objects.DataClasses.EntityCollection`1.Load(List`1 collection, MergeOption mergeOption)
   en System.Data.Entity.Core.Objects.DataClasses.EntityCollection`1.Load(MergeOption mergeOption)
   en System.Data.Entity.Core.Objects.DataClasses.RelatedEnd.DeferredLoad()
   en System.Data.Entity.Core.Objects.Internal.LazyLoadBehavior.LoadProperty[TItem](TItem propertyValue, String relationshipName, String targetRoleName, Boolean mustBeNull, Object wrapperObject)
   en System.Data.Entity.Core.Objects.Internal.LazyLoadBehavior.<>c__DisplayClass7`2.<GetInterceptorDelegate>b__1(TProxy proxy, TItem item)
   en System.Data.Entity.DynamicProxies.Users_D14047590A8F48DF68387E80279D4223F77FA0EE6558BACC53EB074A88A01CBA.get_UsersRoles()
   en BusinessLayer.Mapper.FactoryMapper.<>c__DisplayClass2_0.<MapToDto>b__0(Users user)
   en System.Collections.Generic.List`1.ForEach(Action`1 action)
   en BusinessLayer.Mapper.FactoryMapper.MapToDto(List`1 users)
   en BusinessLayer.UserBusiness.<GetAllUsersAsync>d__3.MoveNext()
--- Fin del seguimiento de la pila de la ubicación anterior donde se produjo la excepción ---
   en System.Runtime.CompilerServices.TaskAwaiter.ThrowForNonSuccess(Task task)
   en System.Runtime.CompilerServices.TaskAwaiter.HandleNonSuccessAndDebuggerNotification(Task task)
   en System.Runtime.CompilerServices.TaskAwaiter`1.GetResult()
   en WebAPIService.Controllers.UsersController.<GetAllUsers>d__4.MoveNext() en C:\Users\emoret\source\repos\WebAPIService\WebAPIService\Controllers\UsersController.cs:línea 39
ERROR 2019-05-02 11:04:13,260 143296ms UsersController        MoveNext           - error in UsersController -> GetUserById: 
System.ObjectDisposedException: The ObjectContext instance has been disposed and can no longer be used for operations that require a connection.
   en System.Data.Entity.Core.Objects.ObjectContext.get_Connection()
   en System.Data.Entity.Core.Objects.ObjectQuery`1.GetResults(Nullable`1 forMergeOption)
   en System.Data.Entity.Core.Objects.ObjectQuery`1.Execute(MergeOption mergeOption)
   en System.Data.Entity.Core.Objects.DataClasses.EntityReference`1.Load(MergeOption mergeOption)
   en System.Data.Entity.Core.Objects.DataClasses.RelatedEnd.DeferredLoad()
   en System.Data.Entity.Core.Objects.Internal.LazyLoadBehavior.LoadProperty[TItem](TItem propertyValue, String relationshipName, String targetRoleName, Boolean mustBeNull, Object wrapperObject)
   en System.Data.Entity.Core.Objects.Internal.LazyLoadBehavior.<>c__DisplayClass7`2.<GetInterceptorDelegate>b__2(TProxy proxy, TItem item)
   en System.Data.Entity.DynamicProxies.UsersRoles_425F43F138CF6E66153D578D6696C863F9757661BE6B3478340CD2F999977A27.get_Roles()
   en BusinessLayer.Mapper.FactoryMapper.MapToDto(List`1 roles)
   en BusinessLayer.Mapper.FactoryMapper.MapToDtoWithPassword(Users user)
   en BusinessLayer.UserBusiness.<GetByIdAsync>d__4.MoveNext()
--- Fin del seguimiento de la pila de la ubicación anterior donde se produjo la excepción ---
   en System.Runtime.CompilerServices.TaskAwaiter.ThrowForNonSuccess(Task task)
   en System.Runtime.CompilerServices.TaskAwaiter.HandleNonSuccessAndDebuggerNotification(Task task)
   en System.Runtime.CompilerServices.TaskAwaiter`1.GetResult()
   en WebAPIService.Controllers.UsersController.<GetUserById>d__5.MoveNext() en C:\Users\emoret\source\repos\WebAPIService\WebAPIService\Controllers\UsersController.cs:línea 55
ERROR 2019-05-02 11:04:23,455 153490ms UsersController        MoveNext           - error in UsersController -> GetUserById: 
System.ObjectDisposedException: The ObjectContext instance has been disposed and can no longer be used for operations that require a connection.
   en System.Data.Entity.Core.Objects.ObjectContext.get_Connection()
   en System.Data.Entity.Core.Objects.ObjectQuery`1.GetResults(Nullable`1 forMergeOption)
   en System.Data.Entity.Core.Objects.ObjectQuery`1.Execute(MergeOption mergeOption)
   en System.Data.Entity.Core.Objects.DataClasses.EntityReference`1.Load(MergeOption mergeOption)
   en System.Data.Entity.Core.Objects.DataClasses.RelatedEnd.DeferredLoad()
   en System.Data.Entity.Core.Objects.Internal.LazyLoadBehavior.LoadProperty[TItem](TItem propertyValue, String relationshipName, String targetRoleName, Boolean mustBeNull, Object wrapperObject)
   en System.Data.Entity.Core.Objects.Internal.LazyLoadBehavior.<>c__DisplayClass7`2.<GetInterceptorDelegate>b__2(TProxy proxy, TItem item)
   en System.Data.Entity.DynamicProxies.UsersRoles_425F43F138CF6E66153D578D6696C863F9757661BE6B3478340CD2F999977A27.get_Roles()
   en BusinessLayer.Mapper.FactoryMapper.MapToDto(List`1 roles)
   en BusinessLayer.Mapper.FactoryMapper.MapToDtoWithPassword(Users user)
   en BusinessLayer.UserBusiness.<GetByIdAsync>d__4.MoveNext()
--- Fin del seguimiento de la pila de la ubicación anterior donde se produjo la excepción ---
   en System.Runtime.CompilerServices.TaskAwaiter.ThrowForNonSuccess(Task task)
   en System.Runtime.CompilerServices.TaskAwaiter.HandleNonSuccessAndDebuggerNotification(Task task)
   en System.Runtime.CompilerServices.TaskAwaiter`1.GetResult()
   en WebAPIService.Controllers.UsersController.<GetUserById>d__5.MoveNext() en C:\Users\emoret\source\repos\WebAPIService\WebAPIService\Controllers\UsersController.cs:línea 55
ERROR 2019-05-02 11:06:55,373 305408ms UsersController        MoveNext           - error in UsersController -> GetUserById: 
System.ObjectDisposedException: The ObjectContext instance has been disposed and can no longer be used for operations that require a connection.
   en System.Data.Entity.Core.Objects.ObjectContext.get_Connection()
   en System.Data.Entity.Core.Objects.ObjectQuery`1.GetResults(Nullable`1 forMergeOption)
   en System.Data.Entity.Core.Objects.ObjectQuery`1.Execute(MergeOption mergeOption)
   en System.Data.Entity.Core.Objects.DataClasses.EntityReference`1.Load(MergeOption mergeOption)
   en System.Data.Entity.Core.Objects.DataClasses.RelatedEnd.DeferredLoad()
   en System.Data.Entity.Core.Objects.Internal.LazyLoadBehavior.LoadProperty[TItem](TItem propertyValue, String relationshipName, String targetRoleName, Boolean mustBeNull, Object wrapperObject)
   en System.Data.Entity.Core.Objects.Internal.LazyLoadBehavior.<>c__DisplayClass7`2.<GetInterceptorDelegate>b__2(TProxy proxy, TItem item)
   en System.Data.Entity.DynamicProxies.UsersRoles_425F43F138CF6E66153D578D6696C863F9757661BE6B3478340CD2F999977A27.get_Roles()
   en BusinessLayer.Mapper.FactoryMapper.MapToDto(List`1 roles)
   en BusinessLayer.Mapper.FactoryMapper.MapToDtoWithPassword(Users user)
   en BusinessLayer.UserBusiness.<GetByIdAsync>d__4.MoveNext()
--- Fin del seguimiento de la pila de la ubicación anterior donde se produjo la excepción ---
   en System.Runtime.CompilerServices.TaskAwaiter.ThrowForNonSuccess(Task task)
   en System.Runtime.CompilerServices.TaskAwaiter.HandleNonSuccessAndDebuggerNotification(Task task)
   en System.Runtime.CompilerServices.TaskAwaiter`1.GetResult()
   en WebAPIService.Controllers.UsersController.<GetUserById>d__5.MoveNext() en C:\Users\emoret\source\repos\WebAPIService\WebAPIService\Controllers\UsersController.cs:línea 55
ERROR 2019-05-02 15:03:35,065 6044523ms UsersController        MoveNext           - error in UsersController -> DeleteUser: 
System.InvalidOperationException: An entity object cannot be referenced by multiple instances of IEntityChangeTracker.
   en DataAccessLayer.Repositories.UserRepository.<Delete>d__6.MoveNext() en C:\Users\emoret\source\repos\WebAPIService\DataAccessLayer\Repositories\UserRepository.cs:línea 136
--- Fin del seguimiento de la pila de la ubicación anterior donde se produjo la excepción ---
   en System.Runtime.CompilerServices.TaskAwaiter.ThrowForNonSuccess(Task task)
   en System.Runtime.CompilerServices.TaskAwaiter.HandleNonSuccessAndDebuggerNotification(Task task)
   en System.Runtime.CompilerServices.TaskAwaiter`1.GetResult()
   en DataAccessLayer.UsersData.<Delete>d__6.MoveNext() en C:\Users\emoret\source\repos\WebAPIService\DataAccessLayer\UsersData.cs:línea 41
--- Fin del seguimiento de la pila de la ubicación anterior donde se produjo la excepción ---
   en System.Runtime.CompilerServices.TaskAwaiter.ThrowForNonSuccess(Task task)
   en System.Runtime.CompilerServices.TaskAwaiter.HandleNonSuccessAndDebuggerNotification(Task task)
   en System.Runtime.CompilerServices.TaskAwaiter`1.GetResult()
   en BusinessLayer.UserBusiness.<DeleteAsync>d__2.MoveNext()
--- Fin del seguimiento de la pila de la ubicación anterior donde se produjo la excepción ---
   en System.Runtime.CompilerServices.TaskAwaiter.ThrowForNonSuccess(Task task)
   en System.Runtime.CompilerServices.TaskAwaiter.HandleNonSuccessAndDebuggerNotification(Task task)
   en System.Runtime.CompilerServices.TaskAwaiter`1.GetResult()
   en WebAPIService.Controllers.UsersController.<DeleteUser>d__8.MoveNext() en C:\Users\emoret\source\repos\WebAPIService\WebAPIService\Controllers\UsersController.cs:línea 112
ERROR 2019-05-02 15:03:42,940 6052398ms UsersController        MoveNext           - error in UsersController -> DeleteUser: 
System.InvalidOperationException: An entity object cannot be referenced by multiple instances of IEntityChangeTracker.
   en DataAccessLayer.Repositories.UserRepository.<Delete>d__6.MoveNext() en C:\Users\emoret\source\repos\WebAPIService\DataAccessLayer\Repositories\UserRepository.cs:línea 136
--- Fin del seguimiento de la pila de la ubicación anterior donde se produjo la excepción ---
   en System.Runtime.CompilerServices.TaskAwaiter.ThrowForNonSuccess(Task task)
   en System.Runtime.CompilerServices.TaskAwaiter.HandleNonSuccessAndDebuggerNotification(Task task)
   en System.Runtime.CompilerServices.TaskAwaiter`1.GetResult()
   en DataAccessLayer.UsersData.<Delete>d__6.MoveNext() en C:\Users\emoret\source\repos\WebAPIService\DataAccessLayer\UsersData.cs:línea 41
--- Fin del seguimiento de la pila de la ubicación anterior donde se produjo la excepción ---
   en System.Runtime.CompilerServices.TaskAwaiter.ThrowForNonSuccess(Task task)
   en System.Runtime.CompilerServices.TaskAwaiter.HandleNonSuccessAndDebuggerNotification(Task task)
   en System.Runtime.CompilerServices.TaskAwaiter`1.GetResult()
   en BusinessLayer.UserBusiness.<DeleteAsync>d__2.MoveNext()
--- Fin del seguimiento de la pila de la ubicación anterior donde se produjo la excepción ---
   en System.Runtime.CompilerServices.TaskAwaiter.ThrowForNonSuccess(Task task)
   en System.Runtime.CompilerServices.TaskAwaiter.HandleNonSuccessAndDebuggerNotification(Task task)
   en System.Runtime.CompilerServices.TaskAwaiter`1.GetResult()
   en WebAPIService.Controllers.UsersController.<DeleteUser>d__8.MoveNext() en C:\Users\emoret\source\repos\WebAPIService\WebAPIService\Controllers\UsersController.cs:línea 112
ERROR 2019-05-02 15:04:38,199 6107657ms UsersController        MoveNext           - error in UsersController -> DeleteUser: 
System.InvalidOperationException: An entity object cannot be referenced by multiple instances of IEntityChangeTracker.
   en DataAccessLayer.Repositories.UserRepository.<Delete>d__6.MoveNext()
--- Fin del seguimiento de la pila de la ubicación anterior donde se produjo la excepción ---
   en System.Runtime.CompilerServices.TaskAwaiter.ThrowForNonSuccess(Task task)
   en System.Runtime.CompilerServices.TaskAwaiter.HandleNonSuccessAndDebuggerNotification(Task task)
   en System.Runtime.CompilerServices.TaskAwaiter`1.GetResult()
   en DataAccessLayer.UsersData.<Delete>d__6.MoveNext()
--- Fin del seguimiento de la pila de la ubicación anterior donde se produjo la excepción ---
   en System.Runtime.CompilerServices.TaskAwaiter.ThrowForNonSuccess(Task task)
   en System.Runtime.CompilerServices.TaskAwaiter.HandleNonSuccessAndDebuggerNotification(Task task)
   en System.Runtime.CompilerServices.TaskAwaiter`1.GetResult()
   en BusinessLayer.UserBusiness.<DeleteAsync>d__2.MoveNext()
--- Fin del seguimiento de la pila de la ubicación anterior donde se produjo la excepción ---
   en System.Runtime.CompilerServices.TaskAwaiter.ThrowForNonSuccess(Task task)
   en System.Runtime.CompilerServices.TaskAwaiter.HandleNonSuccessAndDebuggerNotification(Task task)
   en System.Runtime.CompilerServices.TaskAwaiter`1.GetResult()
   en WebAPIService.Controllers.UsersController.<DeleteUser>d__8.MoveNext() en C:\Users\emoret\source\repos\WebAPIService\WebAPIService\Controllers\UsersController.cs:línea 112
ERROR 2019-05-02 15:05:31,895 6161353ms UsersController        MoveNext           - error in UsersController -> DeleteUser: 
System.InvalidOperationException: An entity object cannot be referenced by multiple instances of IEntityChangeTracker.
   en DataAccessLayer.Repositories.UserRepository.<Delete>d__6.MoveNext()
--- Fin del seguimiento de la pila de la ubicación anterior donde se produjo la excepción ---
   en System.Runtime.CompilerServices.TaskAwaiter.ThrowForNonSuccess(Task task)
   en System.Runtime.CompilerServices.TaskAwaiter.HandleNonSuccessAndDebuggerNotification(Task task)
   en System.Runtime.CompilerServices.TaskAwaiter`1.GetResult()
   en DataAccessLayer.UsersData.<Delete>d__6.MoveNext()
--- Fin del seguimiento de la pila de la ubicación anterior donde se produjo la excepción ---
   en System.Runtime.CompilerServices.TaskAwaiter.ThrowForNonSuccess(Task task)
   en System.Runtime.CompilerServices.TaskAwaiter.HandleNonSuccessAndDebuggerNotification(Task task)
   en System.Runtime.CompilerServices.TaskAwaiter`1.GetResult()
   en BusinessLayer.UserBusiness.<DeleteAsync>d__2.MoveNext()
--- Fin del seguimiento de la pila de la ubicación anterior donde se produjo la excepción ---
   en System.Runtime.CompilerServices.TaskAwaiter.ThrowForNonSuccess(Task task)
   en System.Runtime.CompilerServices.TaskAwaiter.HandleNonSuccessAndDebuggerNotification(Task task)
   en System.Runtime.CompilerServices.TaskAwaiter`1.GetResult()
   en WebAPIService.Controllers.UsersController.<DeleteUser>d__8.MoveNext() en C:\Users\emoret\source\repos\WebAPIService\WebAPIService\Controllers\UsersController.cs:línea 112
ERROR 2019-05-02 15:05:51,363 6180822ms UsersController        MoveNext           - error in UsersController -> DeleteUser: 
System.InvalidOperationException: The object cannot be deleted because it was not found in the ObjectStateManager.
   en DataAccessLayer.Repositories.UserRepository.<Delete>d__6.MoveNext()
--- Fin del seguimiento de la pila de la ubicación anterior donde se produjo la excepción ---
   en System.Runtime.CompilerServices.TaskAwaiter.ThrowForNonSuccess(Task task)
   en System.Runtime.CompilerServices.TaskAwaiter.HandleNonSuccessAndDebuggerNotification(Task task)
   en System.Runtime.CompilerServices.TaskAwaiter`1.GetResult()
   en DataAccessLayer.UsersData.<Delete>d__6.MoveNext()
--- Fin del seguimiento de la pila de la ubicación anterior donde se produjo la excepción ---
   en System.Runtime.CompilerServices.TaskAwaiter.ThrowForNonSuccess(Task task)
   en System.Runtime.CompilerServices.TaskAwaiter.HandleNonSuccessAndDebuggerNotification(Task task)
   en System.Runtime.CompilerServices.TaskAwaiter`1.GetResult()
   en BusinessLayer.UserBusiness.<DeleteAsync>d__2.MoveNext()
--- Fin del seguimiento de la pila de la ubicación anterior donde se produjo la excepción ---
   en System.Runtime.CompilerServices.TaskAwaiter.ThrowForNonSuccess(Task task)
   en System.Runtime.CompilerServices.TaskAwaiter.HandleNonSuccessAndDebuggerNotification(Task task)
   en System.Runtime.CompilerServices.TaskAwaiter`1.GetResult()
   en WebAPIService.Controllers.UsersController.<DeleteUser>d__8.MoveNext() en C:\Users\emoret\source\repos\WebAPIService\WebAPIService\Controllers\UsersController.cs:línea 112
ERROR 2019-05-02 15:11:32,668 69068ms UsersController        MoveNext           - error in UsersController -> DeleteUser: 
System.InvalidOperationException: An entity object cannot be referenced by multiple instances of IEntityChangeTracker.
   en DataAccessLayer.Repositories.UserRepository.<Delete>d__6.MoveNext()
--- Fin del seguimiento de la pila de la ubicación anterior donde se produjo la excepción ---
   en System.Runtime.CompilerServices.TaskAwaiter.ThrowForNonSuccess(Task task)
   en System.Runtime.CompilerServices.TaskAwaiter.HandleNonSuccessAndDebuggerNotification(Task task)
   en System.Runtime.CompilerServices.TaskAwaiter`1.GetResult()
   en DataAccessLayer.UsersData.<Delete>d__6.MoveNext()
--- Fin del seguimiento de la pila de la ubicación anterior donde se produjo la excepción ---
   en System.Runtime.CompilerServices.TaskAwaiter.ThrowForNonSuccess(Task task)
   en System.Runtime.CompilerServices.TaskAwaiter.HandleNonSuccessAndDebuggerNotification(Task task)
   en System.Runtime.CompilerServices.TaskAwaiter`1.GetResult()
   en BusinessLayer.UserBusiness.<DeleteAsync>d__2.MoveNext()
--- Fin del seguimiento de la pila de la ubicación anterior donde se produjo la excepción ---
   en System.Runtime.CompilerServices.TaskAwaiter.ThrowForNonSuccess(Task task)
   en System.Runtime.CompilerServices.TaskAwaiter.HandleNonSuccessAndDebuggerNotification(Task task)
   en System.Runtime.CompilerServices.TaskAwaiter`1.GetResult()
   en WebAPIService.Controllers.UsersController.<DeleteUser>d__8.MoveNext() en C:\Users\emoret\source\repos\WebAPIService\WebAPIService\Controllers\UsersController.cs:línea 112
ERROR 2019-05-15 09:37:04,004 52903ms UsersController        MoveNext           - error in UsersController -> GetAllUsersAsync: 
System.InvalidOperationException: The operation cannot be completed because the DbContext has been disposed.
   en DataAccessLayer.Repositories.UserRepository.<GetAllUsersAsync>d__2.MoveNext() en C:\Users\emoret\source\repos\WebAPIService\DataAccessLayer\Repositories\UserRepository.cs:línea 45
--- Fin del seguimiento de la pila de la ubicación anterior donde se produjo la excepción ---
   en System.Runtime.CompilerServices.TaskAwaiter.ThrowForNonSuccess(Task task)
   en System.Runtime.CompilerServices.TaskAwaiter.HandleNonSuccessAndDebuggerNotification(Task task)
   en System.Runtime.CompilerServices.TaskAwaiter`1.GetResult()
   en DataAccessLayer.UsersData.<GetAllUsersAsync>d__2.MoveNext() en C:\Users\emoret\source\repos\WebAPIService\DataAccessLayer\UsersData.cs:línea 21
--- Fin del seguimiento de la pila de la ubicación anterior donde se produjo la excepción ---
   en System.Runtime.CompilerServices.TaskAwaiter.ThrowForNonSuccess(Task task)
   en System.Runtime.CompilerServices.TaskAwaiter.HandleNonSuccessAndDebuggerNotification(Task task)
   en System.Runtime.CompilerServices.TaskAwaiter`1.GetResult()
   en BusinessLayer.UserBusiness.<GetAllUsersAsync>d__3.MoveNext()
--- Fin del seguimiento de la pila de la ubicación anterior donde se produjo la excepción ---
   en System.Runtime.CompilerServices.TaskAwaiter.ThrowForNonSuccess(Task task)
   en System.Runtime.CompilerServices.TaskAwaiter.HandleNonSuccessAndDebuggerNotification(Task task)
   en System.Runtime.CompilerServices.TaskAwaiter`1.GetResult()
   en WebAPIService.Controllers.UsersController.<GetAllUsers>d__4.MoveNext() en C:\Users\emoret\source\repos\WebAPIService\WebAPIService\Controllers\UsersController.cs:línea 40
ERROR 2019-05-15 09:37:13,942 62840ms UsersController        MoveNext           - error in UsersController -> GetAllUsersAsync: 
System.InvalidOperationException: The operation cannot be completed because the DbContext has been disposed.
   en DataAccessLayer.Repositories.UserRepository.<GetAllUsersAsync>d__2.MoveNext() en C:\Users\emoret\source\repos\WebAPIService\DataAccessLayer\Repositories\UserRepository.cs:línea 45
--- Fin del seguimiento de la pila de la ubicación anterior donde se produjo la excepción ---
   en System.Runtime.CompilerServices.TaskAwaiter.ThrowForNonSuccess(Task task)
   en System.Runtime.CompilerServices.TaskAwaiter.HandleNonSuccessAndDebuggerNotification(Task task)
   en System.Runtime.CompilerServices.TaskAwaiter`1.GetResult()
   en DataAccessLayer.UsersData.<GetAllUsersAsync>d__2.MoveNext() en C:\Users\emoret\source\repos\WebAPIService\DataAccessLayer\UsersData.cs:línea 21
--- Fin del seguimiento de la pila de la ubicación anterior donde se produjo la excepción ---
   en System.Runtime.CompilerServices.TaskAwaiter.ThrowForNonSuccess(Task task)
   en System.Runtime.CompilerServices.TaskAwaiter.HandleNonSuccessAndDebuggerNotification(Task task)
   en System.Runtime.CompilerServices.TaskAwaiter`1.GetResult()
   en BusinessLayer.UserBusiness.<GetAllUsersAsync>d__3.MoveNext()
--- Fin del seguimiento de la pila de la ubicación anterior donde se produjo la excepción ---
   en System.Runtime.CompilerServices.TaskAwaiter.ThrowForNonSuccess(Task task)
   en System.Runtime.CompilerServices.TaskAwaiter.HandleNonSuccessAndDebuggerNotification(Task task)
   en System.Runtime.CompilerServices.TaskAwaiter`1.GetResult()
   en WebAPIService.Controllers.UsersController.<GetAllUsers>d__4.MoveNext() en C:\Users\emoret\source\repos\WebAPIService\WebAPIService\Controllers\UsersController.cs:línea 40
ERROR 2019-05-15 09:37:19,712 68610ms UsersController        MoveNext           - error in UsersController -> GetAllUsersAsync: 
System.InvalidOperationException: The operation cannot be completed because the DbContext has been disposed.
   en DataAccessLayer.Repositories.UserRepository.<GetAllUsersAsync>d__2.MoveNext() en C:\Users\emoret\source\repos\WebAPIService\DataAccessLayer\Repositories\UserRepository.cs:línea 45
--- Fin del seguimiento de la pila de la ubicación anterior donde se produjo la excepción ---
   en System.Runtime.CompilerServices.TaskAwaiter.ThrowForNonSuccess(Task task)
   en System.Runtime.CompilerServices.TaskAwaiter.HandleNonSuccessAndDebuggerNotification(Task task)
   en System.Runtime.CompilerServices.TaskAwaiter`1.GetResult()
   en DataAccessLayer.UsersData.<GetAllUsersAsync>d__2.MoveNext() en C:\Users\emoret\source\repos\WebAPIService\DataAccessLayer\UsersData.cs:línea 21
--- Fin del seguimiento de la pila de la ubicación anterior donde se produjo la excepción ---
   en System.Runtime.CompilerServices.TaskAwaiter.ThrowForNonSuccess(Task task)
   en System.Runtime.CompilerServices.TaskAwaiter.HandleNonSuccessAndDebuggerNotification(Task task)
   en System.Runtime.CompilerServices.TaskAwaiter`1.GetResult()
   en BusinessLayer.UserBusiness.<GetAllUsersAsync>d__3.MoveNext()
--- Fin del seguimiento de la pila de la ubicación anterior donde se produjo la excepción ---
   en System.Runtime.CompilerServices.TaskAwaiter.ThrowForNonSuccess(Task task)
   en System.Runtime.CompilerServices.TaskAwaiter.HandleNonSuccessAndDebuggerNotification(Task task)
   en System.Runtime.CompilerServices.TaskAwaiter`1.GetResult()
   en WebAPIService.Controllers.UsersController.<GetAllUsers>d__4.MoveNext() en C:\Users\emoret\source\repos\WebAPIService\WebAPIService\Controllers\UsersController.cs:línea 40
ERROR 2019-05-15 09:37:23,971 72869ms UsersController        MoveNext           - error in UsersController -> GetAllUsersAsync: 
System.InvalidOperationException: The operation cannot be completed because the DbContext has been disposed.
   en DataAccessLayer.Repositories.UserRepository.<GetAllUsersAsync>d__2.MoveNext() en C:\Users\emoret\source\repos\WebAPIService\DataAccessLayer\Repositories\UserRepository.cs:línea 45
--- Fin del seguimiento de la pila de la ubicación anterior donde se produjo la excepción ---
   en System.Runtime.CompilerServices.TaskAwaiter.ThrowForNonSuccess(Task task)
   en System.Runtime.CompilerServices.TaskAwaiter.HandleNonSuccessAndDebuggerNotification(Task task)
   en System.Runtime.CompilerServices.TaskAwaiter`1.GetResult()
   en DataAccessLayer.UsersData.<GetAllUsersAsync>d__2.MoveNext() en C:\Users\emoret\source\repos\WebAPIService\DataAccessLayer\UsersData.cs:línea 21
--- Fin del seguimiento de la pila de la ubicación anterior donde se produjo la excepción ---
   en System.Runtime.CompilerServices.TaskAwaiter.ThrowForNonSuccess(Task task)
   en System.Runtime.CompilerServices.TaskAwaiter.HandleNonSuccessAndDebuggerNotification(Task task)
   en System.Runtime.CompilerServices.TaskAwaiter`1.GetResult()
   en BusinessLayer.UserBusiness.<GetAllUsersAsync>d__3.MoveNext()
--- Fin del seguimiento de la pila de la ubicación anterior donde se produjo la excepción ---
   en System.Runtime.CompilerServices.TaskAwaiter.ThrowForNonSuccess(Task task)
   en System.Runtime.CompilerServices.TaskAwaiter.HandleNonSuccessAndDebuggerNotification(Task task)
   en System.Runtime.CompilerServices.TaskAwaiter`1.GetResult()
   en WebAPIService.Controllers.UsersController.<GetAllUsers>d__4.MoveNext() en C:\Users\emoret\source\repos\WebAPIService\WebAPIService\Controllers\UsersController.cs:línea 40
